<?xml version="1.0" encoding="UTF-8"?>
<testng-results skipped="0" failed="1" total="1" passed="0">
  <reporter-output>
  </reporter-output>
  <suite name="inetBankingV1" duration-ms="8247" started-at="2020-02-02T18:17:06Z" finished-at="2020-02-02T18:17:14Z">
    <groups>
    </groups>
    <test name="BankingApp Test" duration-ms="8247" started-at="2020-02-02T18:17:06Z" finished-at="2020-02-02T18:17:14Z">
      <class name="com.inetBanking.testCases.TC_LoginTest_001">
        <test-method status="PASS" signature="setup(java.lang.String)[pri:0, instance:com.inetBanking.testCases.TC_LoginTest_001@57baeedf]" name="setup" is-config="true" duration-ms="4657" started-at="2020-02-02T12:17:06Z" finished-at="2020-02-02T12:17:11Z">
          <params>
            <param index="0">
              <value>
                <![CDATA[chrome]]>
              </value>
            </param>
          </params>
          <reporter-output>
          </reporter-output>
        </test-method> <!-- setup -->
        <test-method status="FAIL" signature="loginTest()[pri:0, instance:com.inetBanking.testCases.TC_LoginTest_001@57baeedf]" name="loginTest" duration-ms="2572" started-at="2020-02-02T12:17:11Z" finished-at="2020-02-02T12:17:13Z">
          <exception class="java.lang.AssertionError">
            <message>
              <![CDATA[expected [true] but found [false]]]>
            </message>
            <full-stacktrace>
              <![CDATA[java.lang.AssertionError: expected [true] but found [false]
	at org.testng.Assert.fail(Assert.java:94)
	at org.testng.Assert.failNotEquals(Assert.java:496)
	at org.testng.Assert.assertTrue(Assert.java:42)
	at org.testng.Assert.assertTrue(Assert.java:52)
	at com.inetBanking.testCases.TC_LoginTest_001.loginTest(TC_LoginTest_001.java:38)
	at sun.reflect.NativeMethodAccessorImpl.invoke0(Native Method)
	at sun.reflect.NativeMethodAccessorImpl.invoke(Unknown Source)
	at sun.reflect.DelegatingMethodAccessorImpl.invoke(Unknown Source)
	at java.lang.reflect.Method.invoke(Unknown Source)
	at org.testng.internal.MethodInvocationHelper.invokeMethod(MethodInvocationHelper.java:85)
	at org.testng.internal.Invoker.invokeMethod(Invoker.java:639)
	at org.testng.internal.Invoker.invokeTestMethod(Invoker.java:816)
	at org.testng.internal.Invoker.invokeTestMethods(Invoker.java:1124)
	at org.testng.internal.TestMethodWorker.invokeTestMethods(TestMethodWorker.java:125)
	at org.testng.internal.TestMethodWorker.run(TestMethodWorker.java:108)
	at org.testng.TestRunner.privateRun(TestRunner.java:774)
	at org.testng.TestRunner.run(TestRunner.java:624)
	at org.testng.SuiteRunner.runTest(SuiteRunner.java:359)
	at org.testng.SuiteRunner.runSequentially(SuiteRunner.java:354)
	at org.testng.SuiteRunner.privateRun(SuiteRunner.java:312)
	at org.testng.SuiteRunner.run(SuiteRunner.java:261)
	at org.testng.SuiteRunnerWorker.runSuite(SuiteRunnerWorker.java:52)
	at org.testng.SuiteRunnerWorker.run(SuiteRunnerWorker.java:86)
	at org.testng.TestNG.runSuitesSequentially(TestNG.java:1191)
	at org.testng.TestNG.runSuitesLocally(TestNG.java:1116)
	at org.testng.TestNG.run(TestNG.java:1024)
	at org.testng.remote.AbstractRemoteTestNG.run(AbstractRemoteTestNG.java:114)
	at org.testng.remote.RemoteTestNG.initAndRun(RemoteTestNG.java:251)
	at org.testng.remote.RemoteTestNG.main(RemoteTestNG.java:77)
]]>
            </full-stacktrace>
          </exception> <!-- java.lang.AssertionError -->
          <reporter-output>
          </reporter-output>
        </test-method> <!-- loginTest -->
        <test-method status="PASS" signature="tearDown()[pri:0, instance:com.inetBanking.testCases.TC_LoginTest_001@57baeedf]" name="tearDown" is-config="true" duration-ms="795" started-at="2020-02-02T12:17:13Z" finished-at="2020-02-02T12:17:14Z">
          <reporter-output>
          </reporter-output>
        </test-method> <!-- tearDown -->
      </class> <!-- com.inetBanking.testCases.TC_LoginTest_001 -->
    </test> <!-- BankingApp Test -->
  </suite> <!-- inetBankingV1 -->
</testng-results>
